tests/500instruments-100kOrders.in
40
0-39 o
.
23 S 1 JNCW 4939 585
26 B 2 DMRH 8991 191
23 B 3 RCHF 14094 925
22 S 4 KQAO 9063 970
4 S 5 PKNA 14811 911
16 S 6 KPLA 2440 834
22 B 7 XBVQ 9344 67
35 B 8 OAOV 10758 484
39 B 9 TTJM 10707 129
10 B 10 RABD 7335 239
15 B 11 HYVS 1236 62
36 S 12 JDKE 15258 685
19 S 13 YRPP 13915 506
30 B 14 HYLH 11548 752
0 B 15 WABF 9663 310
29 B 16 LQPZ 1934 335
27 S 17 IPPZ 15595 655
36 B 18 UVJG 17566 754
18 B 19 ICKU 3299 48
8 B 20 TQMN 7962 931
1 S 21 UKIR 4907 9
36 B 22 NDJW 11567 526
39 B 23 UEAZ 13464 680
28 S 24 ASJA 17576 534
29 B 25 QMUB 7012 777
29 S 26 VNCS 14908 330
35 S 27 HFYS 10033 206
31 B 28 FDQZ 5592 868
29 B 29 WISB 19181 33
35 S 30 ZATA 16504 556
8 B 31 FXFJ 5584 525
28 S 32 IQPD 764 739
15 B 33 LFLP 281 180
12 S 34 QZIM 5914 152
8 S 35 QQNJ 5865 382
0 S 36 ADHP 4414 329
17 B 37 YQME 8069 333
34 B 38 JLDQ 17792 308
35 S 39 QRWL 1534 454
30 S 40 OMKM 5666 643
13 S 41 ZEAU 12835 161
12 S 42 MVOJ 4139 952
32 B 43 XBVQ 6600 749
10 B 44 ZWLU 7959 676
29 B 45 DATU 7396 286
2 S 46 HXXP 1306 292
14 S 47 RXMD 5475 488
26 B 48 IACA 19831 356
26 B 49 FDQZ 8270 807
24 S 50 PLYK 8220 491
33 B 51 BCZS 5914 897
2 B 52 ZJNL 12547 965
16 S 53 CLVT 12344 639
23 S 54 OUYR 9403 724
35 B 55 OIDC 1730 280
1 S 56 MZPD 13113 229
8 B 57 DDGV 16746 888
32 B 58 BNLD 13222 32
39 B 59 NUIN 9905 345
17 B 60 OVDB 11939 706
27 S 61 WABF 7011 961
0 S 62 BWFB 9257 261
0 S 63 ASRX 5782 994
11 B 64 XVSU 14175 214
9 S 65 TMFX 2642 938
16 S 66 ZHSN 8266 675
2 B 67 ASRX 15334 942
35 S 68 MVOJ 12332 570
35 B 69 PKNA 11910 791
20 B 70 ZPBI 11041 219
24 B 71 BZMJ 5654 398
7 B 72 BZEJ 13682 65
37 B 73 NHCH 14825 423
16 S 74 QMZS 11728 200
5 B 75 XBVQ 125 479
3 S 76 KQAO 580 750
3 S 77 UGJO 9321 435
19 S 78 KWID 2025 798
35 S 79 TUWP 19940 688
10 S 80 PWSN 15171 847
2 S 81 KQAO 9754 393
22 B 82 BRET 15113 209
35 B 83 VSCR 19487 868
24 S 84 NBXI 18527 192
17 B 85 ENTQ 5030 988
25 B 86 UWVG 4819 537
1 B 87 IACA 8853 185
13 S 88 KKCN 7365 362
13 S 89 LDUM 17812 559
1 B 90 TDAT 11414 337
14 B 91 OIDC 19701 434
8 B 92 UMPG 4610 831
30 B 93 DATU 8857 857
16 S 94 DUSF 16032 781
35 B 95 UNDP 13073 312
27 S 96 GEVQ 8576 975
11 S 97 DAWR 13284 634
0 B 98 HYLH 3587 401
8 B 99 WKWR 4896 10
36 B 100 INAX 18201 881
12 B 101 UNDP 11005 31
31 S 102 YFBY 1423 164
9 S 103 NSFC 514 417
19 S 104 UHWS 8683 932
15 B 105 RCHF 5459 571
26 S 106 YUUR 17316 718
36 B 107 KDJY 11230 454
16 B 108 ZVIO 19766 947
27 B 109 PWMS 7318 185
36 S 110 IBIF 1614 985
18 S 111 REAH 8490 970
36 S 112 WEAX 13982 739
23 B 113 YABY 4612 983
34 B 114 LRDR 8323 80
8 B 115 SOSM 1226 946
15 B 116 XAJS 16033 437
22 B 117 JGEQ 5459 669
10 S 118 WABF 12370 275
36 B 119 ZVIO 1905 348
30 B 120 RXNF 15240 715
0 B 121 QRXI 15884 528
31 B 122 GRCW 4102 884
31 S 123 GVVX 19955 628
22 B 124 KKCN 11590 449
32 S 125 YVEY 19598 82
36 S 126 NDJW 14 568
38 S 127 MPCM 14575 931
27 B 128 JGEQ 16029 4
36 S 129 WDCK 8572 600
16 S 130 TKFX 7920 565
30 S 131 LTHY 808 905
20 S 132 KQAO 11395 834
28 S 133 HXXP 5090 849
0 S 134 FTMN 4433 745
38 S 135 BWFB 19678 953
29 S 136 PQXX 9235 33
4 S 137 OXSC 12482 567
21 B 138 YOJC 14060 823
9 B 139 ZUBK 16709 429
28 S 140 HXXP 9899 472
33 B 141 OMKM 14849 161
25 B 142 UGJO 1910 877
35 S 143 HQUS 4238 355
23 S 144 NXBM 11530 582
7 B 145 JGEQ 6118 814
28 B 146 BVRD 13500 850
26 S 147 EYTI 14143 964
0 S 148 UBUU 19426 944
28 B 149 SKYK 5054 622
27 S 150 ICKU 4093 503
32 S 151 CYER 3327 973
6 S 152 TFYF 19763 820
28 B 153 SBXK 1484 541
10 B 154 HYVS 4263 227
3 S 155 CLVT 10934 770
7 B 156 QMZS 11182 54
11 S 157 QGGV 18469 111
33 S 158 IQPD 180 158
26 S 159 DAWR 17652 131
37 B 160 RYVH 14541 295
35 S 161 BIPE 11621 428
13 B 162 CHZU 9129 201
21 S 163 EDAZ 7118 876
21 B 164 AFJY 17550 401
7 B 165 ENTQ 8322 259
15 B 166 IPVB 5674 689
24 S 167 AWOB 15301 915
9 S 168 WDCK 3551 773
19 S 169 IPPZ 4459 136
36 B 170 UGJO 16131 397
12 S 171 IULN 6391 612
8 B 172 OZAF 14385 799
4 B 173 PLYK 9411 334
13 S 174 NNAG 14463 561
0 B 175 OXKT 10905 775
24 B 176 ZZDA 18615 164
11 B 177 VQLK 5887 821
12 S 178 IXOG 1678 321
3 S 179 PLYK 8508 989
12 S 180 JSBG 6605 919
16 S 181 TKFX 13036 606
23 B 182 NPFL 10794 92
12 S 183 RFEB 7872 751
14 B 184 KWID 2388 364
9 S 185 NMGJ 7084 549
33 S 186 CMDC 14166 968
24 S 187 QRXI 1331 571
6 S 188 ONZY 15499 451
6 B 189 UHWS 4884 406
35 B 190 YJMH 13326 557
18 S 191 NUIN 13663 728
31 S 192 QMUB 11900 268
19 B 193 LRDR 13107 869
22 B 194 GRCW 9665 617
7 S 195 FAPG 6662 316
25 B 196 YUED 828 886
20 S 197 MQMS 8077 37
28 S 198 NBCZ 8319 572
27 S 199 GXUG 593 16
24 B 200 ASRX 9368 684
2 B 201 PLYK 19970 639
12 S 202 YATI 7698 442
7 S 203 YCLF 19357 350
33 S 204 CLVT 8964 268
33 S 205 HQLW 7452 241
12 S 206 OBOU 1281 979
6 B 207 URMC 10733 751
16 S 208 TRQC 16095 121
39 S 209 FCYA 11883 743
24 B 210 TMFX 5792 618
28 S 211 EYTI 1465 51
7 S 212 ONZY 2845 920
24 B 213 TMFX 8336 270
15 B 214 NSFC 17823 861
28 B 215 SKFK 10947 810
24 B 216 UOLR 12528 925
28 B 217 JDKE 2680 392
33 B 218 HIXM 695 87
25 B 219 OMKM 8567 825
11 B 220 HKFO 6168 736
27 B 221 AAEM 3134 547
7 B 222 PHFJ 12854 566
16 S 223 OAOV 9770 23
30 B 224 MVOJ 19030 860
10 S 225 YQME 17056 771
2 B 226 DNEW 14864 453
10 S 227 GWDO 2630 624
10 B 228 BOXK 6897 962
16 B 229 WKWR 17148 233
3 B 230 JTHI 3753 759
5 S 231 LOAJ 3845 196
26 S 232 CSNF 17035 580
18 S 233 QQNJ 7068 451
16 B 234 ADHP 10966 917
6 S 235 KQTY 17197 746
33 B 236 QGGV 4572 820
26 S 237 SBXK 5001 13
39 B 238 TKFX 7001 326
35 B 239 OXSC 15519 788
8 B 240 SSCV 5285 561
36 S 241 DPEJ 12349 326
24 B 242 OUYR 5697 869
5 S 243 OUYR 14630 636
7 S 244 EAAF 18516 288
38 B 245 LRDR 7569 453
4 B 246 NUIN 7169 6
38 B 247 USII 1113 3
21 S 248 TNRY 3693 422
13 S 249 HNZV 10216 276
20 B 250 LMOP 14145 177
37 S 251 FAMN 454 927
36 B 252 WQMV 7671 126
25 S 253 YQME 9660 248
20 B 254 BRET 9821 891
19 S 255 WSPN 5501 871
16 B 256 CFWA 15018 502
21 B 257 EYTI 15250 386
7 S 258 ZJNL 1456 695
4 S 259 FAMN 12477 37
5 S 260 QCWA 2753 369
23 S 261 REAH 16201 386
34 S 262 HHRF 11220 462
32 B 263 WQNP 2408 396
4 S 264 RLYZ 11406 169
0 S 265 XBVQ 15024 542
30 B 266 KSNN 5620 68
14 B 267 PHFJ 12768 569
17 B 268 EGWC 13987 496
38 S 269 AWOB 19115 746
7 B 270 FROY 10671 314
35 S 271 PHPF 6245 586
11 S 272 UGJO 9417 769
30 S 273 ZPFY 116 162
12 S 274 RYVH 18979 139
33 B 275 NPFL 6875 276
15 B 276 DPEJ 6144 397
16 B 277 PQXX 8038 955
29 B 278 ZBCH 10510 587
14 B 279 UEAZ 10760 515
21 B 280 MBZH 3968 248
7 S 281 ZIIJ 17435 634
14 B 282 OPIS 9490 133
12 B 283 ADHP 18950 953
18 B 284 KDJY 8590 12
21 S 285 LQPZ 7604 739
5 B 286 HQUS 5164 975
39 B 287 FXFJ 436 775
3 B 288 NNAG 10339 727
10 B 289 BZEJ 11962 512
8 B 290 JTHI 2021 775
34 B 291 BXNX 11320 46
13 S 292 RZGX 14652 725
4 B 293 UWVG 1649 769
24 S 294 TUWP 19869 654
39 S 295 FKVQ 12116 55
22 B 296 OSUM 12640 212
37 S 297 CYER 19770 644
38 S 298 OZAF 3269 833
29 S 299 MHSE 5437 769
18 B 300 UWVG 10278 820
24 S 301 MEPA 12799 114
12 S 302 OSUM 19598 930
19 S 303 TUWP 12416 457
0 S 304 EZVK 5364 611
38 B 305 DZAG 14859 363
8 B 306 PQXX 5873 326
2 S 307 BEVM 17392 300
36 S 308 AAEM 13894 367
20 B 309 ZIIJ 9322 295
37 S 310 FROY 3522 636
26 B 311 LTHY 834 150
38 S 312 SAXX 4463 759
23 S 313 SSCV 3399 244
15 S 314 JRYS 17579 567
6 S 315 XVSU 2952 779
20 B 316 PWMS 13713 632
9 B 317 SWVO 17975 117
14 S 318 UJKL 8577 297
31 S 319 NDXH 6272 438
15 S 320 RLYZ 6390 3
25 B 321 POYY 9375 962
23 B 322 ZWLU 7515 676
17 S 323 YRPP 7141 823
6 B 324 SPEE 80 577
16 S 325 BEVM 11897 856
32 B 326 WKWR 17177 922
19 B 327 SKYK 1163 609
3 S 328 HVSF 17279 520
11 S 329 NUIN 11985 570
12 S 330 OMKM 2372 86
18 B 331 UMPG 15631 343
10 S 332 LSVG 11534 511
30 S 333 BZMJ 13783 406
27 B 334 HVSF 11652 226
11 B 335 ZJNL 15028 309
9 S 336 FKVQ 837 727
37 B 337 WSPN 13991 222
30 S 338 QYDI 15891 787
9 B 339 JNCW 11688 776
8 S 340 GWDO 17000 696
7 B 341 FKNR 5381 619
4 S 342 KQAO 2198 305
5 S 343 XBVQ 7796 479
26 S 344 SBXK 10987 846
3 B 345 BIPE 4823 63
14 S 346 QIDO 11028 804
30 S 347 ONZY 7200 310
6 S 348 WEAX 14363 598
15 S 349 ZUBX 13013 59
36 S 350 FRVV 324 53
31 B 351 JNCW 19331 211
13 B 352 DNEW 15682 899
