tests/hard-example1.in
10
0-9 o
.
0 B 101 AAPL 150 10
1 B 102 MSFT 200 20
2 B 103 AMZN 250 15
3 B 104 GOOG 1000 5
4 B 105 TSLA 600 8
5 S 201 AAPL 150 10
6 S 202 MSFT 200 20
7 S 203 AMZN 250 15
8 S 204 GOOG 1000 5
9 S 205 TSLA 600 8
.
0 C 101
1 C 102
2 C 103
3 C 104
4 C 105
5 w 201
6 w 202
7 w 203
8 w 204
9 w 205
.
0-9 x
