tests/hard-example2.in
20
0-19 o
0 B 101 AAPL 100 5
1 B 102 MSFT 210 10
2 B 103 GOOG 1050 2
3 B 104 TSLA 620 8
4 B 105 AMZN 310 7
10 S 201 AAPL 100 5
11 S 202 MSFT 210 10
12 S 203 GOOG 1050 2
13 S 204 TSLA 620 8
14 S 205 AMZN 310 7
0 C 101
3 C 104
0-19 x
