tests/hard-example3.in
40
0-39 o
.
4 B 1 INTC 1979 43
7 S 2 GOOG 496 27
4 S 3 GOOG 333 16
32 S 4 INTC 1013 52
5 B 5 GOOG 1706 73
20 B 6 NFLX 750 13
4 B 7 FB 13 40
6 B 8 FB 564 85
12 S 9 NVDA 821 49
15 B 10 NFLX 62 42
26 S 11 AAPL 1504 63
25 B 12 AMD 356 25
22 S 13 AAPL 1042 84
5 S 14 AMZN 1742 89
15 B 15 GOOG 329 25
33 S 16 GOOG 1952 37
36 B 17 AAPL 284 24
38 S 18 TSLA 1239 53
28 B 19 INTC 636 54
27 S 20 FB 1777 81
13 B 21 NVDA 1029 4
6 S 22 NFLX 263 59
4 S 23 TSLA 575 88
37 S 24 AMZN 990 33
25 S 25 MSFT 1285 41
23 B 26 AAPL 1590 34
10 B 27 AMZN 1585 56
30 B 28 TSLA 123 45
20 S 29 NVDA 1366 75
19 B 30 MSFT 1841 92
28 B 31 NFLX 1266 1
32 S 32 AAPL 1643 9
22 S 33 NVDA 1628 48
2 B 34 FB 1761 70
8 S 35 AMD 58 44
23 B 36 NFLX 517 59
18 S 37 TSLA 1518 44
22 S 38 NFLX 163 12
39 S 39 GOOG 292 27
19 B 40 AMD 334 52
38 B 41 AMZN 100 8
18 S 42 NVDA 1631 94
35 S 43 GOOG 1580 2
20 S 44 INTC 106 43
27 B 45 AAPL 1009 67
33 S 46 MSFT 1221 4
2 B 47 FB 782 100
35 S 48 AMD 179 34
3 S 49 MSFT 1028 30
25 S 50 AAPL 617 12
5 B 51 FB 197 100
1 B 52 INTC 1035 44
3 S 53 INTC 568 29
29 S 54 AAPL 1154 46
38 S 55 NVDA 1129 71
6 B 56 NVDA 856 76
0 S 57 TSLA 699 89
35 S 58 FB 543 10
6 S 59 NVDA 1184 62
3 S 60 AMD 1312 67
5 B 61 FB 794 5
38 B 62 FB 742 20
24 S 63 MSFT 1650 95
29 B 64 TSLA 271 37
12 S 65 FB 46 56
39 S 66 AMZN 1812 5
33 S 67 GOOG 1771 78
16 B 68 AMD 8 56
18 S 69 INTC 471 53
38 S 70 AMD 1288 28
12 S 71 AMD 1481 19
16 S 72 FB 93 44
37 B 73 NFLX 1250 2
36 B 74 NFLX 1097 55
38 B 75 AMZN 1803 75
20 B 76 AAPL 243 58
6 B 77 INTC 165 94
9 S 78 AAPL 531 71
10 S 79 NVDA 1559 34
27 S 80 TSLA 1932 8
21 S 81 AMD 1415 42
10 S 82 AAPL 1945 66
24 B 83 AAPL 98 48
7 S 84 TSLA 1390 48
15 S 85 AMZN 1497 78
39 S 86 FB 1695 67
36 B 87 TSLA 937 23
27 B 88 NVDA 1241 22
30 S 89 INTC 792 10
27 S 90 TSLA 635 36
37 B 91 AMD 1443 87
26 B 92 TSLA 1499 60
17 B 93 AAPL 1276 84
31 S 94 AMD 1655 41
23 S 95 INTC 857 71
37 S 96 INTC 1447 25
30 B 97 AAPL 899 8
15 B 98 GOOG 1337 2
7 B 99 AMZN 109 77
17 S 100 FB 993 98
28 B 101 AAPL 36 37
30 S 102 AMD 809 80
11 B 103 INTC 662 69
13 S 104 AMZN 796 76
13 B 105 AAPL 817 38
4 B 106 AAPL 1413 76
3 B 107 AMD 978 95
9 S 108 NFLX 1217 19
10 S 109 NVDA 1607 39
8 S 110 AAPL 1882 77
12 B 111 TSLA 1834 48
1 B 112 TSLA 1105 69
28 S 113 TSLA 1888 2
36 B 114 AMZN 884 18
12 B 115 AAPL 1934 40
28 B 116 NVDA 132 21
6 B 117 MSFT 1429 77
11 B 118 NFLX 1522 93
33 B 119 AMZN 1880 82
32 S 120 INTC 1343 89
24 B 121 INTC 958 29
39 B 122 NFLX 623 37
20 B 123 GOOG 714 57
15 B 124 AMD 605 85
5 S 125 GOOG 784 35
4 B 126 FB 1639 22
21 S 127 NVDA 455 6
25 B 128 GOOG 1245 62
6 B 129 AMZN 1746 99
36 B 130 FB 540 81
4 S 131 TSLA 100 24
16 B 132 FB 293 85
6 B 133 INTC 337 83
16 S 134 AMD 1174 44
20 S 135 TSLA 960 45
32 S 136 TSLA 587 67
19 B 137 NFLX 365 63
20 S 138 AAPL 1633 37
1 S 139 TSLA 1644 70
31 S 140 AMZN 1826 84
21 S 141 NFLX 1556 50
7 S 142 AMZN 309 5
29 B 143 INTC 1875 42
8 B 144 NFLX 710 27
28 S 145 MSFT 1829 23
26 S 146 AAPL 292 63
31 B 147 AAPL 1995 87
34 S 148 AMD 768 96
1 B 149 AMZN 1887 79
36 B 150 AMZN 250 48
9 S 151 INTC 1375 89
0 B 152 FB 1781 46
28 B 153 GOOG 50 85
29 B 154 AAPL 1659 92
13 S 155 INTC 1648 19
6 B 156 TSLA 1814 79
21 S 157 NVDA 1999 67
14 B 158 MSFT 1630 40
30 B 159 AAPL 1891 12
18 B 160 INTC 1400 53
2 S 161 GOOG 1173 15
22 B 162 AMD 398 29
39 S 163 GOOG 798 73
17 S 164 NVDA 1832 88
38 B 165 AMZN 206 50
12 S 166 TSLA 662 53
35 S 167 FB 949 32
20 B 168 FB 884 3
34 B 169 GOOG 1115 17
12 S 170 AMZN 1118 79
17 B 171 FB 1060 96
39 B 172 TSLA 667 93
9 B 173 TSLA 329 58
3 S 174 INTC 1270 99
5 S 175 GOOG 1290 19
6 B 176 MSFT 331 1
12 B 177 NFLX 1983 79
4 B 178 AMZN 876 38
27 S 179 GOOG 1140 73
22 S 180 AMZN 240 51
31 B 181 AMD 1901 48
8 S 182 AMZN 61 31
6 S 183 NFLX 1782 36
9 B 184 AMZN 1183 4
30 S 185 NVDA 1721 12
5 B 186 INTC 1902 64
33 S 187 TSLA 1220 98
14 B 188 INTC 1476 81
21 B 189 FB 1791 40
5 B 190 INTC 1575 15
5 B 191 AAPL 1969 46
16 B 192 TSLA 1613 66
12 B 193 NVDA 228 100
4 S 194 AMD 546 5
35 S 195 INTC 168 3
23 S 196 AMD 1641 66
19 S 197 INTC 280 16
6 B 198 INTC 859 46
0 B 199 MSFT 1738 89
4 S 200 NFLX 1693 34
24 S 201 INTC 1899 45
12 B 202 INTC 1497 3
5 B 203 AMZN 548 62
20 S 204 MSFT 375 79
25 B 205 MSFT 477 19
32 B 206 FB 74 91
37 B 207 INTC 1764 8
32 S 208 AMD 1272 60
35 B 209 AAPL 1451 77
31 S 210 INTC 1212 42
33 S 211 GOOG 365 38
15 B 212 AAPL 115 91
3 S 213 MSFT 936 54
23 S 214 TSLA 535 25
2 B 215 TSLA 1485 71
30 S 216 MSFT 840 6
15 B 217 AMZN 510 68
28 S 218 MSFT 383 28
25 S 219 NVDA 939 45
8 S 220 AMZN 799 48
24 B 221 AAPL 1141 51
28 B 222 MSFT 1479 43
29 B 223 AAPL 1669 75
1 S 224 TSLA 326 50
25 S 225 AMZN 10 89
10 S 226 AMZN 1179 55
35 S 227 FB 523 27
38 S 228 NVDA 1496 86
9 S 229 FB 1797 100
11 B 230 MSFT 1997 41
19 S 231 NVDA 1562 51
18 B 232 AAPL 1297 60
35 S 233 TSLA 1372 72
15 B 234 INTC 1077 87
12 S 235 MSFT 799 32
11 S 236 NFLX 451 55
13 B 237 TSLA 1044 92
12 B 238 AMD 11 10
15 B 239 GOOG 950 9
9 B 240 AMZN 244 35
22 S 241 NFLX 204 91
20 S 242 AMD 966 4
29 B 243 INTC 1482 52
23 B 244 NVDA 749 7
5 S 245 GOOG 280 11
29 S 246 MSFT 1737 92
35 S 247 INTC 460 88
20 B 248 MSFT 377 9
16 S 249 INTC 1943 96
25 B 250 AMD 511 80
26 S 251 TSLA 29 17
13 S 252 AMZN 800 18
36 S 253 AMD 580 2
6 S 254 NVDA 1560 21
0 B 255 AMD 728 59
12 B 256 AMD 887 65
16 S 257 NFLX 85 29
22 B 258 AMZN 894 37
31 B 259 FB 1207 54
12 B 260 FB 1716 97
5 B 261 AMD 1835 9
29 S 262 TSLA 745 93
30 B 263 NVDA 1825 35
22 S 264 AMZN 21 81
8 S 265 TSLA 1170 36
11 S 266 AMD 972 12
16 S 267 FB 1824 17
21 S 268 NFLX 1706 15
24 B 269 TSLA 1997 68
14 S 270 AMZN 1646 50
25 S 271 AAPL 353 9
36 B 272 AMZN 624 72
23 S 273 TSLA 920 95
38 B 274 MSFT 139 74
8 S 275 AAPL 1851 7
37 S 276 AMD 1855 39
18 S 277 NVDA 446 64
14 B 278 AMD 1984 97
36 S 279 NFLX 819 88
34 S 280 NFLX 1031 51
28 B 281 AMD 1621 17
13 S 282 FB 611 56
31 B 283 AMD 57 11
39 S 284 AMD 637 1
34 S 285 AMZN 197 25
2 S 286 MSFT 1386 47
9 S 287 AMD 936 41
24 S 288 MSFT 284 53
6 S 289 MSFT 1685 86
26 B 290 AMZN 1659 78
4 S 291 AAPL 1247 5
33 B 292 AAPL 106 38
23 B 293 NFLX 851 39
28 S 294 MSFT 1013 93
39 S 295 NVDA 319 27
1 B 296 AMZN 1587 46
9 B 297 NFLX 1484 100
21 B 298 INTC 1736 50
34 B 299 NFLX 772 93
2 B 300 GOOG 1861 96
31 B 301 AMZN 1629 75
36 S 302 AAPL 686 94
15 S 303 AMD 92 68
4 B 304 NVDA 1550 73
8 B 305 TSLA 627 48
39 B 306 AMZN 1858 89
6 S 307 AMD 596 1
35 B 308 AMZN 517 55
23 B 309 INTC 397 44
10 B 310 INTC 230 34
21 S 311 AAPL 1160 92
34 B 312 TSLA 351 82
14 B 313 GOOG 384 13
23 B 314 TSLA 1047 6
1 B 315 GOOG 1088 87
33 B 316 MSFT 603 47
27 S 317 AMZN 626 86
23 B 318 AMZN 1521 61
31 B 319 TSLA 649 67
12 S 320 MSFT 266 66
32 B 321 AMZN 395 26
32 B 322 AAPL 157 84
39 S 323 INTC 1181 32
22 S 324 TSLA 1370 27
24 S 325 AMZN 558 89
9 S 326 FB 315 81
36 B 327 AAPL 1779 74
37 S 328 TSLA 1279 97
18 S 329 NVDA 865 88
2 B 330 INTC 1893 55
34 B 331 INTC 1887 32
27 S 332 FB 1875 20
24 B 333 AMZN 1042 44
8 B 334 TSLA 1621 6
17 S 335 INTC 1820 40
19 B 336 INTC 780 10
5 B 337 TSLA 1002 54
36 S 338 AAPL 913 93
36 B 339 INTC 991 87
35 S 340 AMD 1439 92
23 B 341 AAPL 1569 94
10 B 342 AMZN 1988 14
16 B 343 INTC 1135 11
9 B 344 NFLX 1863 75
5 S 345 FB 1884 18
28 S 346 MSFT 1534 80
17 B 347 TSLA 1756 94
37 B 348 NVDA 1004 9
30 S 349 INTC 213 100
37 S 350 NFLX 1173 91
33 B 351 NFLX 1444 93
13 S 352 TSLA 1126 65
34 B 353 AMD 1629 62
21 B 354 NVDA 1873 51
32 B 355 NVDA 1470 41
9 B 356 MSFT 971 24
28 S 357 AMD 1942 58
6 B 358 AAPL 1377 61
19 B 359 AAPL 1614 89
19 B 360 NVDA 1999 82
23 B 361 MSFT 1166 89
36 B 362 INTC 1657 2
34 B 363 INTC 1130 85
6 S 364 AAPL 913 61
39 S 365 TSLA 110 93
1 S 366 TSLA 188 94
36 B 367 AMZN 1640 86
27 S 368 FB 1962 97
39 B 369 AMZN 1323 14
30 S 370 GOOG 1541 78
19 S 371 TSLA 310 76
12 S 372 INTC 514 38
0 S 373 FB 248 27
22 S 374 TSLA 1774 47
0 S 375 INTC 856 76
38 B 376 MSFT 1912 70
32 B 377 AAPL 451 81
13 B 378 MSFT 1351 27
29 B 379 INTC 263 46
11 B 380 GOOG 1459 73
4 S 381 INTC 1845 40
12 S 382 AMZN 5 31
26 S 383 AAPL 657 20
33 S 384 GOOG 954 83
13 B 385 NFLX 1230 6
17 S 386 MSFT 1032 30
29 S 387 NFLX 1036 68
0 B 388 NVDA 1579 25
